Traceback (most recent call last):
  File "C:\Users\aster\Documents_\Hochschule\Data Analysis Hausarbeit\Hausarbeit\venv\lib\site-packages\nbclient\client.py", line 626, in _async_poll_for_reply
    msg = await ensure_async(self.kc.shell_channel.get_msg(timeout=new_timeout))
  File "C:\Users\aster\Documents_\Hochschule\Data Analysis Hausarbeit\Hausarbeit\venv\lib\site-packages\nbclient\util.py", line 96, in ensure_async
    result = await obj
  File "C:\Users\aster\Documents_\Hochschule\Data Analysis Hausarbeit\Hausarbeit\venv\lib\site-packages\jupyter_client\channels.py", line 230, in get_msg
    raise Empty
_queue.Empty

During handling of the above exception, another exception occurred:

Traceback (most recent call last):
  File "C:\Users\aster\Documents_\Hochschule\Data Analysis Hausarbeit\Hausarbeit\venv\lib\site-packages\jupyter_cache\executors\utils.py", line 51, in single_nb_execution
    executenb(
  File "C:\Users\aster\Documents_\Hochschule\Data Analysis Hausarbeit\Hausarbeit\venv\lib\site-packages\nbclient\client.py", line 1093, in execute
    return NotebookClient(nb=nb, resources=resources, km=km, **kwargs).execute()
  File "C:\Users\aster\Documents_\Hochschule\Data Analysis Hausarbeit\Hausarbeit\venv\lib\site-packages\nbclient\util.py", line 84, in wrapped
    return just_run(coro(*args, **kwargs))
  File "C:\Users\aster\Documents_\Hochschule\Data Analysis Hausarbeit\Hausarbeit\venv\lib\site-packages\nbclient\util.py", line 62, in just_run
    return loop.run_until_complete(coro)
  File "C:\Users\aster\AppData\Local\Programs\Python\Python39\lib\asyncio\base_events.py", line 642, in run_until_complete
    return future.result()
  File "C:\Users\aster\Documents_\Hochschule\Data Analysis Hausarbeit\Hausarbeit\venv\lib\site-packages\nbclient\client.py", line 559, in async_execute
    await self.async_execute_cell(
  File "C:\Users\aster\Documents_\Hochschule\Data Analysis Hausarbeit\Hausarbeit\venv\lib\site-packages\nbclient\client.py", line 838, in async_execute_cell
    exec_reply = await self.task_poll_for_reply
  File "C:\Users\aster\Documents_\Hochschule\Data Analysis Hausarbeit\Hausarbeit\venv\lib\site-packages\nbclient\client.py", line 650, in _async_poll_for_reply
    await self._async_handle_timeout(timeout, cell)
  File "C:\Users\aster\Documents_\Hochschule\Data Analysis Hausarbeit\Hausarbeit\venv\lib\site-packages\nbclient\client.py", line 697, in _async_handle_timeout
    raise CellTimeoutError.error_from_timeout_and_cell(
nbclient.exceptions.CellTimeoutError: A cell timed out while it was being executed, after 30 seconds.
The message was: Cell execution timed out.
Here is a preview of the cell contents:
-------------------
['# Modell f√ºr den Gradient Boosting Classifier instanzieren', 'gbc = GradientBoostingClassifier(**hyper_params ,random_state=42)', '', '# Datensatz vorbereiten', "X = df_one_hot_encoded_data.drop('id', axis=1)"]
...
["fit_gbc = gbc.fit(X_train, y_train['response'])", '', '# Vorhersagen ', 'y_pred = fit_gbc.predict(X)', 'y_pred']
-------------------

